Workbook

Sheet Paste Run 1
A1: ExperimentName | B1: Subject | C1: Session | D1: Clock.Information | E1: DataFile.Basename | F1: Display.RefreshRate | G1: ExperimentVersion | H1: Group | I1: Instructions.Duration | J1: Instructions.DurationError | K1: Instructions.OffsetDelay | L1: Instructions.OffsetTime | M1: Instructions.OnsetDelay | N1: Instructions.OnsetTime | O1: Instructions.OnsetToOnsetTime | P1: Instructions.RESP | Q1: Instructions.RT | R1: Instructions.RTTime | S1: RandomSeed | T1: RuntimeCapabilities | U1: RuntimeVersion | V1: RuntimeVersionExpected | W1: SessionDate | X1: SessionStartDateTimeUtc | Y1: SessionTime | Z1: StudioVersion | AA1: Trigger.DEVICE | AB1: Trigger.Duration | AC1: Trigger.DurationError | AD1: Trigger.OffsetTime | AE1: Trigger.OnsetDelay | AF1: Trigger.OnsetTime | AG1: Trigger.OnsetToOnsetTime | AH1: Trigger.RESP | AI1: Trigger.RT | AJ1: Trigger.RTTime | AK1: Block | AL1: aptTrials | AM1: aptTrials.Cycle | AN1: aptTrials.Sample | AO1: Choice | AP1: currentChoice | AQ1: decideduration | AR1: decideNew.ACC | AS1: decideNew.CRESP | AT1: decideNew.Duration | AU1: decideNew.DurationError | AV1: decideNew.FinishTime | AW1: decideNew.OffsetDelay | AX1: decideNew.OffsetTime | AY1: decideNew.OnsetDelay | AZ1: decideNew.OnsetTime | BA1: decideNew.OnsetToOnsetTime | BB1: decideNew.PreRelease | BC1: decideNew.RESP | BD1: decideNew.RT | BE1: decideNew.RTTime | BF1: decideNew.StartTime | BG1: decideNew.TargetOffsetTime | BH1: decideNew.TargetOnsetTime | BI1: inputduration | BJ1: inputresponse.ACC | BK1: inputresponse.CRESP | BL1: inputresponse.DEVICE | BM1: inputresponse.Duration | BN1: inputresponse.DurationError | BO1: inputresponse.FinishTime | BP1: inputresponse.OffsetTime | BQ1: inputresponse.OnsetDelay | BR1: inputresponse.OnsetTime | BS1: inputresponse.OnsetToOnsetTime | BT1: inputresponse.PreRelease | BU1: inputresponse.RESP | BV1: inputresponse.RT | BW1: inputresponse.RTTime | BX1: inputresponse.StartTime | BY1: inputresponse.TargetOffsetTime | BZ1: inputresponse.TargetOnsetTime | CA1: ISI | CB1: ISI.ACC | CC1: ISI.CRESP | CD1: ISI.Duration | CE1: ISI.DurationError | CF1: ISI.FinishTime | CG1: ISI.OffsetDelay | CH1: ISI.OffsetTime | CI1: ISI.OnsetDelay | CJ1: ISI.OnsetTime | CK1: ISI.OnsetToOnsetTime | CL1: ISI.PreRelease | CM1: ISI.RESP | CN1: ISI.RT | CO1: ISI.RTTime | CP1: ISI.StartTime | CQ1: ISI.TargetOffsetTime | CR1: ISI.TargetOnsetTime | CS1: maxpos | CT1: minpos | CU1: pos1 | CV1: pos10 | CW1: pos11 | CX1: pos2 | CY1: pos3 | CZ1: pos4 | DA1: pos5 | DB1: pos6 | DC1: pos7 | DD1: pos8 | DE1: pos9 | DF1: price | DG1: Procedure | DH1: Running | DI1: start.Duration | DJ1: start.DurationError | DK1: start.OffsetTime | DL1: start.OnsetDelay | DM1: start.OnsetTime | DN1: start.OnsetToOnsetTime | DO1: submitduration | DP1: submitted.ACC | DQ1: submitted.CRESP | DR1: submitted.Duration | DS1: submitted.DurationError | DT1: submitted.FinishTime | DU1: submitted.OffsetDelay | DV1: submitted.OffsetTime | DW1: submitted.OnsetDelay | DX1: submitted.OnsetTime | DY1: submitted.OnsetToOnsetTime | DZ1: submitted.PreRelease | EA1: submitted.RESP | EB1: submitted.RT | EC1: submitted.RTTime | ED1: submitted.StartTime | EE1: submitted.TargetOffsetTime | EF1: submitted.TargetOnsetTime | EG1: trialnumber
A2: R01_NE_APT Run 1_Penultimate Prices EP3_Mar22 | B2: XXXX | C2: 1 | D2: <?xml version="1.0"?>\n<Clock xmlns:dt="urn:schemas-microsoft-com:datatypes"><Description dt:dt="string">E-Prime Primary Realtime Clock</Description><StartTime><Timestamp dt:dt="int">0</Timestamp><DateUtc dt:dt="string">2019-07-05T13:15:01Z</DateUtc></StartTime><FrequencyChanges><FrequencyChange><Frequency dt:dt="r8">2531445</Frequency><Timestamp dt:dt="r8">12159273989</Timestamp><Current dt:dt="r8">0</Current><DateUtc dt:dt="string">2019-07-05T13:15:01Z</DateUtc></FrequencyChange></FrequencyChanges></Clock>\n | E2: R01_NE_APT Run 1_Penultimate Prices EP3_Mar22-01002-1 | F2: 59.956 | G2: 1.0.0.107 | H2: 1 | I2: 6000 | J2: -57 | K2: 0 | L2: 24000 | M2: 57 | N2: 18157 | O2: 5954 | Q2: 0 | R2: 0 | S2: -725311415 | T2: Full | U2: 3.0.3.80 | V2: 3.0.3.80 | W2: 5/7/2019 | X2: 7/5/2019 13:15 | Y2: 0.38542824 | Z2: 3.0.3.82 | AA2: Keyboard | AB2: -1 | AC2: -999999 | AD2: 18100 | AE2: 41 | AF2: 6999 | AG2: 0 | AH2: 5 | AI2: 11101 | AJ2: 18100 | AK2: 1 | AL2: 1 | AM2: 1 | AN2: 1 | AO2: 7 | AP2: ? | AQ2: 4000 | AR2: 0 | AT2: 4000 | AU2: -11 | AV2: 28000 | AW2: 0 | AX2: 28000 | AY2: 11 | AZ2: 24111 | BA2: 4003 | BB2: 100 | BD2: 0 | BE2: 0 | BF2: 24002 | BG2: 28000 | BH2: 24100 | BI2: 7000 | BJ2: 0 | BL2: Keyboard | BM2: 7000 | BN2: -999999 | BO2: 32874 | BP2: 32874 | BQ2: 56 | BR2: 31634 | BS2: 0 | BT2: 100 | BU2: 1 | BV2: 1240 | BW2: 32874 | BX2: 31581 | BY2: 38478 | BZ2: 31578 | CA2: 6000 | CB2: 0 | CD2: 6000 | CE2: -3 | CF2: 41000 | CG2: 0 | CH2: 41000 | CI2: 3 | CJ2: 35103 | CK2: 0 | CL2: 100 | CN2: 0 | CO2: 0 | CP2: 35000 | CQ2: 41000 | CR2: 35100 | CS2: 15 | CT2: 4 | CU2: 0 | CV2: 9 | CW2: 10 | CX2: 1 | CY2: 2 | CZ2: 3 | DA2: 4 | DB2: 5 | DC2: 6 | DD2: 7 | DE2: 8 | DF2: $0.01 each? | DG2: aptTrialProc | DH2: aptTrials | DI2: 0 | DJ2: 0 | DK2: 28114 | DL2: 14 | DM2: 28114 | DN2: 67 | DO2: 7000 | DP2: 0 | DR2: 7000 | DS2: -4835 | DT2: 35000 | DU2: 0 | DV2: 35000 | DW2: 4835 | DX2: 32935 | DY2: 2168 | DZ2: 100 | EB2: 0 | EC2: 0 | ED2: 32877 | EE2: 35000 | EF2: 28100 | EG2: 1
A3: R01_NE_APT Run 1_Penultimate Prices EP3_Mar22 | B3: XXXX | C3: 1 | D3: <?xml version="1.0"?>\n<Clock xmlns:dt="urn:schemas-microsoft-com:datatypes"><Description dt:dt="string">E-Prime Primary Realtime Clock</Description><StartTime><Timestamp dt:dt="int">0</Timestamp><DateUtc dt:dt="string">2019-07-05T13:15:01Z</DateUtc></StartTime><FrequencyChanges><FrequencyChange><Frequency dt:dt="r8">2531445</Frequency><Timestamp dt:dt="r8">12159273989</Timestamp><Current dt:dt="r8">0</Current><DateUtc dt:dt="string">2019-07-05T13:15:01Z</DateUtc></FrequencyChange></FrequencyChanges></Clock>\n | E3: R01_NE_APT Run 1_Penultimate Prices EP3_Mar22-01002-1 | F3: 59.956 | G3: 1.0.0.107 | H3: 1 | I3: 6000 | J3: -57 | K3: 0 | L3: 24000 | M3: 57 | N3: 18157 | O3: 5954 | Q3: 0 | R3: 0 | S3: -725311415 | T3: Full | U3: 3.0.3.80 | V3: 3.0.3.80 | W3: 5/7/2019 | X3: 7/5/2019 13:15 | Y3: 0.38542824 | Z3: 3.0.3.82 | AA3: Keyboard | AB3: -1 | AC3: -999999 | AD3: 18100 | AE3: 41 | AF3: 6999 | AG3: 0 | AH3: 5 | AI3: 11101 | AJ3: 18100 | AK3: 2 | AL3: 2 | AM3: 1 | AN3: 2 | AO3: 5 | AP3: ? | AQ3: 4000 | AR3: 0 | AT3: 4000 | AU3: -7 | AV3: 45000 | AW3: 0 | AX3: 45000 | AY3: 7 | AZ3: 41107 | BA3: 4003 | BB3: 100 | BD3: 0 | BE3: 0 | BF3: 41005 | BG3: 45000 | BH3: 41100 | BI3: 7000 | BJ3: 0 | BL3: Keyboard | BM3: 7000 | BN3: -999999 | BO3: 48793 | BP3: 48793 | BQ3: 65 | BR3: 46962 | BS3: 0 | BT3: 100 | BU3: 1 | BV3: 1831 | BW3: 48793 | BX3: 46901 | BY3: 53797 | BZ3: 46897 | CA3: 12000 | CB3: 0 | CD3: 12000 | CE3: -16 | CF3: 64000 | CG3: 0 | CH3: 64000 | CI3: 16 | CJ3: 52116 | CK3: 0 | CL3: 100 | CN3: 0 | CO3: 0 | CP3: 52000 | CQ3: 64000 | CR3: 52100 | CS3: 15 | CT3: 4 | CU3: 0 | CV3: 9 | CW3: 10 | CX3: 1 | CY3: 2 | CZ3: 3 | DA3: 4 | DB3: 5 | DC3: 6 | DD3: 7 | DE3: 8 | DF3: $5.00 each? | DG3: aptTrialProc | DH3: aptTrials | DI3: 0 | DJ3: 1 | DK3: 45111 | DL3: 10 | DM3: 45110 | DN3: 51 | DO3: 7000 | DP3: 0 | DR3: 7000 | DS3: -3747 | DT3: 52000 | DU3: 0 | DV3: 52000 | DW3: 3747 | DX3: 48847 | DY3: 3269 | DZ3: 100 | EB3: 0 | EC3: 0 | ED3: 48795 | EE3: 52000 | EF3: 45100 | EG3: 2
A4: R01_NE_APT Run 1_Penultimate Prices EP3_Mar22 | B4: XXXX | C4: 1 | D4: <?xml version="1.0"?>\n<Clock xmlns:dt="urn:schemas-microsoft-com:datatypes"><Description dt:dt="string">E-Prime Primary Realtime Clock</Description><StartTime><Timestamp dt:dt="int">0</Timestamp><DateUtc dt:dt="string">2019-07-05T13:15:01Z</DateUtc></StartTime><FrequencyChanges><FrequencyChange><Frequency dt:dt="r8">2531445</Frequency><Timestamp dt:dt="r8">12159273989</Timestamp><Current dt:dt="r8">0</Current><DateUtc dt:dt="string">2019-07-05T13:15:01Z</DateUtc></FrequencyChange></FrequencyChanges></Clock>\n | E4: R01_NE_APT Run 1_Penultimate Prices EP3_Mar22-01002-1 | F4: 59.956 | G4: 1.0.0.107 | H4: 1 | I4: 6000 | J4: -57 | K4: 0 | L4: 24000 | M4: 57 | N4: 18157 | O4: 5954 | Q4: 0 | R4: 0 | S4: -725311415 | T4: Full | U4: 3.0.3.80 | V4: 3.0.3.80 | W4: 5/7/2019 | X4: 7/5/2019 13:15 | Y4: 0.38542824 | Z4: 3.0.3.82 | AA4: Keyboard | AB4: -1 | AC4: -999999 | AD4: 18100 | AE4: 41 | AF4: 6999 | AG4: 0 | AH4: 5 | AI4: 11101 | AJ4: 18100 | AK4: 3 | AL4: 3 | AM4: 1 | AN4: 3 | AO4: 0 | AP4: ? | AQ4: 4000 | AR4: 0 | AT4: 4000 | AU4: -8 | AV4: 68000 | AW4: 0 | AX4: 68000 | AY4: 8 | AZ4: 64108 | BA4: 4003 | BB4: 100 | BD4: 0 | BE4: 0 | BF4: 64005 | BG4: 68000 | BH4: 64100 | BI4: 7000 | BJ4: 0 | BL4: Keyboard | BM4: 7000 | BN4: -999999 | BO4: 71927 | BP4: 71927 | BQ4: 53 | BR4: 70980 | BS4: 0 | BT4: 100 | BU4: 1 | BV4: 947 | BW4: 71927 | BX4: 70930 | BY4: 77827 | BZ4: 70927 | CA4: 8000 | CB4: 0 | CD4: 8000 | CE4: 0 | CF4: 83000 | CG4: 0 | CH4: 83000 | CI4: 0 | CJ4: 75100 | CK4: 0 | CL4: 100 | CN4: 0 | CO4: 0 | CP4: 75000 | CQ4: 83000 | CR4: 75100 | CS4: 15 | CT4: 4 | CU4: 0 | CV4: 9 | CW4: 10 | CX4: 1 | CY4: 2 | CZ4: 3 | DA4: 4 | DB4: 5 | DC4: 6 | DD4: 7 | DE4: 8 | DF4: $50.00 each? | DG4: aptTrialProc | DH4: aptTrials | DI4: 0 | DJ4: 0 | DK4: 68111 | DL4: 11 | DM4: 68111 | DN4: 50 | DO4: 7000 | DP4: 0 | DR4: 7000 | DS4: -3881 | DT4: 75000 | DU4: 0 | DV4: 75000 | DW4: 3881 | DX4: 71981 | DY4: 3119 | DZ4: 100 | EB4: 0 | EC4: 0 | ED4: 71929 | EE4: 75000 | EF4: 68100 | EG4: 3
A5: R01_NE_APT Run 1_Penultimate Prices EP3_Mar22 | B5: XXXX | C5: 1 | D5: <?xml version="1.0"?>\n<Clock xmlns:dt="urn:schemas-microsoft-com:datatypes"><Description dt:dt="string">E-Prime Primary Realtime Clock</Description><StartTime><Timestamp dt:dt="int">0</Timestamp><DateUtc dt:dt="string">2019-07-05T13:15:01Z</DateUtc></StartTime><FrequencyChanges><FrequencyChange><Frequency dt:dt="r8">2531445</Frequency><Timestamp dt:dt="r8">12159273989</Timestamp><Current dt:dt="r8">0</Current><DateUtc dt:dt="string">2019-07-05T13:15:01Z</DateUtc></FrequencyChange></FrequencyChanges></Clock>\n | E5: R01_NE_APT Run 1_Penultimate Prices EP3_Mar22-01002-1 | F5: 59.956 | G5: 1.0.0.107 | H5: 1 | I5: 6000 | J5: -57 | K5: 0 | L5: 24000 | M5: 57 | N5: 18157 | O5: 5954 | Q5: 0 | R5: 0 | S5: -725311415 | T5: Full | U5: 3.0.3.80 | V5: 3.0.3.80 | W5: 5/7/2019 | X5: 7/5/2019 13:15 | Y5: 0.38542824 | Z5: 3.0.3.82 | AA5: Keyboard | AB5: -1 | AC5: -999999 | AD5: 18100 | AE5: 41 | AF5: 6999 | AG5: 0 | AH5: 5 | AI5: 11101 | AJ5: 18100 | AK5: 4 | AL5: 4 | AM5: 1 | AN5: 4 | AO5: 8 | AP5: ? | AQ5: 4000 | AR5: 0 | AT5: 4000 | AU5: -6 | AV5: 87000 | AW5: 0 | AX5: 87000 | AY5: 6 | AZ5: 83106 | BA5: 4003 | BB5: 100 | BD5: 0 | BE5: 0 | BF5: 83005 | BG5: 87000 | BH5: 83100 | BI5: 7000 | BJ5: 0 | BL5: Keyboard | BM5: 7000 | BN5: -999999 | BO5: 89638 | BP5: 89637 | BQ5: 53 | BR5: 88994 | BS5: 0 | BT5: 100 | BU5: 1 | BV5: 643 | BW5: 89637 | BX5: 88945 | BY5: 95841 | BZ5: 88941 | CA5: 4000 | CB5: 0 | CD5: 4000 | CE5: -14 | CF5: 98000 | CG5: 0 | CH5: 98000 | CI5: 14 | CJ5: 94114 | CK5: 0 | CL5: 100 | CN5: 0 | CO5: 0 | CP5: 94000 | CQ5: 98000 | CR5: 94100 | CS5: 15 | CT5: 4 | CU5: 0 | CV5: 9 | CW5: 10 | CX5: 1 | CY5: 2 | CZ5: 3 | DA5: 4 | DB5: 5 | DC5: 6 | DD5: 7 | DE5: 8 | DF5: $0.00 each? | DG5: aptTrialProc | DH5: aptTrials | DI5: 0 | DJ5: 0 | DK5: 87109 | DL5: 9 | DM5: 87109 | DN5: 50 | DO5: 7000 | DP5: 0 | DR5: 7000 | DS5: -2594 | DT5: 94000 | DU5: 0 | DV5: 94000 | DW5: 2594 | DX5: 89694 | DY5: 4420 | DZ5: 100 | EB5: 0 | EC5: 0 | ED5: 89640 | EE5: 94000 | EF5: 87100 | EG5: 4
A6: R01_NE_APT Run 1_Penultimate Prices EP3_Mar22 | B6: XXXX | C6: 1 | D6: <?xml version="1.0"?>\n<Clock xmlns:dt="urn:schemas-microsoft-com:datatypes"><Description dt:dt="string">E-Prime Primary Realtime Clock</Description><StartTime><Timestamp dt:dt="int">0</Timestamp><DateUtc dt:dt="string">2019-07-05T13:15:01Z</DateUtc></StartTime><FrequencyChanges><FrequencyChange><Frequency dt:dt="r8">2531445</Frequency><Timestamp dt:dt="r8">12159273989</Timestamp><Current dt:dt="r8">0</Current><DateUtc dt:dt="string">2019-07-05T13:15:01Z</DateUtc></FrequencyChange></FrequencyChanges></Clock>\n | E6: R01_NE_APT Run 1_Penultimate Prices EP3_Mar22-01002-1 | F6: 59.956 | G6: 1.0.0.107 | H6: 1 | I6: 6000 | J6: -57 | K6: 0 | L6: 24000 | M6: 57 | N6: 18157 | O6: 5954 | Q6: 0 | R6: 0 | S6: -725311415 | T6: Full | U6: 3.0.3.80 | V6: 3.0.3.80 | W6: 5/7/2019 | X6: 7/5/2019 13:15 | Y6: 0.38542824 | Z6: 3.0.3.82 | AA6: Keyboard | AB6: -1 | AC6: -999999 | AD6: 18100 | AE6: 41 | AF6: 6999 | AG6: 0 | AH6: 5 | AI6: 11101 | AJ6: 18100 | AK6: 5 | AL6: 5 | AM6: 1 | AN6: 5 | AO6: 2 | AP6: ? | AQ6: 4000 | AR6: 0 | AT6: 4000 | AU6: 0 | AV6: 102000 | AW6: 0 | AX6: 102000 | AY6: 0 | AZ6: 98100 | BA6: 4003 | BB6: 100 | BD6: 0 | BE6: 0 | BF6: 98005 | BG6: 102000 | BH6: 98100 | BI6: 7000 | BJ6: 0 | BL6: Keyboard | BM6: 7000 | BN6: -999999 | BO6: 106980 | BP6: 106980 | BQ6: 51 | BR6: 104455 | BS6: 0 | BT6: 100 | BU6: 1 | BV6: 2525 | BW6: 106980 | BX6: 104408 | BY6: 111304 | BZ6: 104404 | CA6: 4000 | CB6: 0 | CD6: 4000 | CE6: -9 | CF6: 113000 | CG6: 0 | CH6: 113000 | CI6: 9 | CJ6: 109109 | CK6: 0 | CL6: 100 | CN6: 0 | CO6: 0 | CP6: 109000 | CQ6: 113000 | CR6: 109100 | CS6: 15 | CT6: 4 | CU6: 0 | CV6: 9 | CW6: 10 | CX6: 1 | CY6: 2 | CZ6: 3 | DA6: 4 | DB6: 5 | DC6: 6 | DD6: 7 | DE6: 8 | DF6: $15.00 each? | DG6: aptTrialProc | DH6: aptTrials | DI6: 0 | DJ6: 0 | DK6: 102103 | DL6: 3 | DM6: 102103 | DN6: 51 | DO6: 7000 | DP6: 0 | DR6: 7000 | DS6: -4924 | DT6: 109000 | DU6: 0 | DV6: 109000 | DW6: 4924 | DX6: 107024 | DY6: 2085 | DZ6: 100 | EB6: 0 | EC6: 0 | ED6: 106982 | EE6: 109000 | EF6: 102100 | EG6: 5
A7: R01_NE_APT Run 1_Penultimate Prices EP3_Mar22 | B7: XXXX | C7: 1 | D7: <?xml version="1.0"?>\n<Clock xmlns:dt="urn:schemas-microsoft-com:datatypes"><Description dt:dt="string">E-Prime Primary Realtime Clock</Description><StartTime><Timestamp dt:dt="int">0</Timestamp><DateUtc dt:dt="string">2019-07-05T13:15:01Z</DateUtc></StartTime><FrequencyChanges><FrequencyChange><Frequency dt:dt="r8">2531445</Frequency><Timestamp dt:dt="r8">12159273989</Timestamp><Current dt:dt="r8">0</Current><DateUtc dt:dt="string">2019-07-05T13:15:01Z</DateUtc></FrequencyChange></FrequencyChanges></Clock>\n | E7: R01_NE_APT Run 1_Penultimate Prices EP3_Mar22-01002-1 | F7: 59.956 | G7: 1.0.0.107 | H7: 1 | I7: 6000 | J7: -57 | K7: 0 | L7: 24000 | M7: 57 | N7: 18157 | O7: 5954 | Q7: 0 | R7: 0 | S7: -725311415 | T7: Full | U7: 3.0.3.80 | V7: 3.0.3.80 | W7: 5/7/2019 | X7: 7/5/2019 13:15 | Y7: 0.38542824 | Z7: 3.0.3.82 | AA7: Keyboard | AB7: -1 | AC7: -999999 | AD7: 18100 | AE7: 41 | AF7: 6999 | AG7: 0 | AH7: 5 | AI7: 11101 | AJ7: 18100 | AK7: 6 | AL7: 6 | AM7: 1 | AN7: 6 | AO7: 8 | AP7: ? | AQ7: 4000 | AR7: 0 | AT7: 4000 | AU7: -12 | AV7: 117000 | AW7: 0 | AX7: 117000 | AY7: 12 | AZ7: 113112 | BA7: 4003 | BB7: 100 | BD7: 0 | BE7: 0 | BF7: 113005 | BG7: 117000 | BH7: 113100 | BI7: 7000 | BJ7: 0 | BL7: Keyboard | BM7: 7000 | BN7: -999999 | BO7: 120771 | BP7: 120771 | BQ7: 54 | BR7: 120401 | BS7: 0 | BT7: 100 | BU7: 1 | BV7: 370 | BW7: 120771 | BX7: 120352 | BY7: 127247 | BZ7: 120347 | CA7: 2000 | CB7: 0 | CD7: 2000 | CE7: -3 | CF7: 126000 | CG7: 0 | CH7: 126000 | CI7: 3 | CJ7: 124103 | CK7: 0 | CL7: 100 | CN7: 0 | CO7: 0 | CP7: 124000 | CQ7: 126000 | CR7: 124100 | CS7: 15 | CT7: 4 | CU7: 0 | CV7: 9 | CW7: 10 | CX7: 1 | CY7: 2 | CZ7: 3 | DA7: 4 | DB7: 5 | DC7: 6 | DD7: 7 | DE7: 8 | DF7: $0.05 each? | DG7: aptTrialProc | DH7: aptTrials | DI7: 0 | DJ7: 0 | DK7: 117115 | DL7: 15 | DM7: 117115 | DN7: 50 | DO7: 7000 | DP7: 0 | DR7: 7000 | DS7: -3734 | DT7: 124000 | DU7: 0 | DV7: 124000 | DW7: 3734 | DX7: 120834 | DY7: 3269 | DZ7: 100 | EB7: 0 | EC7: 0 | ED7: 120773 | EE7: 124000 | EF7: 117100 | EG7: 6
A8: R01_NE_APT Run 1_Penultimate Prices EP3_Mar22 | B8: XXXX | C8: 1 | D8: <?xml version="1.0"?>\n<Clock xmlns:dt="urn:schemas-microsoft-com:datatypes"><Description dt:dt="string">E-Prime Primary Realtime Clock</Description><StartTime><Timestamp dt:dt="int">0</Timestamp><DateUtc dt:dt="string">2019-07-05T13:15:01Z</DateUtc></StartTime><FrequencyChanges><FrequencyChange><Frequency dt:dt="r8">2531445</Frequency><Timestamp dt:dt="r8">12159273989</Timestamp><Current dt:dt="r8">0</Current><DateUtc dt:dt="string">2019-07-05T13:15:01Z</DateUtc></FrequencyChange></FrequencyChanges></Clock>\n | E8: R01_NE_APT Run 1_Penultimate Prices EP3_Mar22-01002-1 | F8: 59.956 | G8: 1.0.0.107 | H8: 1 | I8: 6000 | J8: -57 | K8: 0 | L8: 24000 | M8: 57 | N8: 18157 | O8: 5954 | Q8: 0 | R8: 0 | S8: -725311415 | T8: Full | U8: 3.0.3.80 | V8: 3.0.3.80 | W8: 5/7/2019 | X8: 7/5/2019 13:15 | Y8: 0.38542824 | Z8: 3.0.3.82 | AA8: Keyboard | AB8: -1 | AC8: -999999 | AD8: 18100 | AE8: 41 | AF8: 6999 | AG8: 0 | AH8: 5 | AI8: 11101 | AJ8: 18100 | AK8: 7 | AL8: 7 | AM8: 1 | AN8: 7 | AO8: 0 | AP8: ? | AQ8: 4000 | AR8: 0 | AT8: 4000 | AU8: -5 | AV8: 130000 | AW8: 0 | AX8: 130000 | AY8: 5 | AZ8: 126105 | BA8: 4003 | BB8: 100 | BD8: 0 | BE8: 0 | BF8: 126005 | BG8: 130000 | BH8: 126100 | BI8: 7000 | BJ8: 0 | BL8: Keyboard | BM8: 7000 | BN8: -999999 | BO8: 133722 | BP8: 133722 | BQ8: 63 | BR8: 133377 | BS8: 0 | BT8: 100 | BU8: 1 | BV8: 345 | BW8: 133722 | BX8: 133318 | BY8: 140214 | BZ8: 133314 | CA8: 8000 | CB8: 0 | CD8: 8000 | CE8: -13 | CF8: 145000 | CG8: 0 | CH8: 145000 | CI8: 13 | CJ8: 137113 | CK8: 0 | CL8: 100 | CN8: 0 | CO8: 0 | CP8: 137000 | CQ8: 145000 | CR8: 137100 | CS8: 15 | CT8: 4 | CU8: 0 | CV8: 9 | CW8: 10 | CX8: 1 | CY8: 2 | CZ8: 3 | DA8: 4 | DB8: 5 | DC8: 6 | DD8: 7 | DE8: 8 | DF8: $40.00 each? | DG8: aptTrialProc | DH8: aptTrials | DI8: 0 | DJ8: 0 | DK8: 130108 | DL8: 8 | DM8: 130108 | DN8: 50 | DO8: 7000 | DP8: 0 | DR8: 7000 | DS8: -3694 | DT8: 137000 | DU8: 0 | DV8: 137000 | DW8: 3694 | DX8: 133794 | DY8: 3319 | DZ8: 100 | EB8: 0 | EC8: 0 | ED8: 133726 | EE8: 137000 | EF8: 130100 | EG8: 7
A9: R01_NE_APT Run 1_Penultimate Prices EP3_Mar22 | B9: XXXX | C9: 1 | D9: <?xml version="1.0"?>\n<Clock xmlns:dt="urn:schemas-microsoft-com:datatypes"><Description dt:dt="string">E-Prime Primary Realtime Clock</Description><StartTime><Timestamp dt:dt="int">0</Timestamp><DateUtc dt:dt="string">2019-07-05T13:15:01Z</DateUtc></StartTime><FrequencyChanges><FrequencyChange><Frequency dt:dt="r8">2531445</Frequency><Timestamp dt:dt="r8">12159273989</Timestamp><Current dt:dt="r8">0</Current><DateUtc dt:dt="string">2019-07-05T13:15:01Z</DateUtc></FrequencyChange></FrequencyChanges></Clock>\n | E9: R01_NE_APT Run 1_Penultimate Prices EP3_Mar22-01002-1 | F9: 59.956 | G9: 1.0.0.107 | H9: 1 | I9: 6000 | J9: -57 | K9: 0 | L9: 24000 | M9: 57 | N9: 18157 | O9: 5954 | Q9: 0 | R9: 0 | S9: -725311415 | T9: Full | U9: 3.0.3.80 | V9: 3.0.3.80 | W9: 5/7/2019 | X9: 7/5/2019 13:15 | Y9: 0.38542824 | Z9: 3.0.3.82 | AA9: Keyboard | AB9: -1 | AC9: -999999 | AD9: 18100 | AE9: 41 | AF9: 6999 | AG9: 0 | AH9: 5 | AI9: 11101 | AJ9: 18100 | AK9: 8 | AL9: 8 | AM9: 1 | AN9: 8 | AO9: 3 | AP9: ? | AQ9: 4000 | AR9: 0 | AT9: 4000 | AU9: -2 | AV9: 149000 | AW9: 0 | AX9: 149000 | AY9: 2 | AZ9: 145102 | BA9: 4003 | BB9: 100 | BD9: 0 | BE9: 0 | BF9: 145005 | BG9: 149000 | BH9: 145100 | BI9: 7000 | BJ9: 0 | BL9: Keyboard | BM9: 7000 | BN9: -999999 | BO9: 152033 | BP9: 152033 | BQ9: 75 | BR9: 151724 | BS9: 0 | BT9: 100 | BU9: 1 | BV9: 309 | BW9: 152033 | BX9: 151654 | BY9: 158549 | BZ9: 151649 | CA9: 8000 | CB9: 0 | CD9: 8000 | CE9: -11 | CF9: 164000 | CG9: 0 | CH9: 164000 | CI9: 11 | CJ9: 156111 | CK9: 0 | CL9: 100 | CN9: 0 | CO9: 0 | CP9: 156000 | CQ9: 164000 | CR9: 156100 | CS9: 15 | CT9: 4 | CU9: 0 | CV9: 9 | CW9: 10 | CX9: 1 | CY9: 2 | CZ9: 3 | DA9: 4 | DB9: 5 | DC9: 6 | DD9: 7 | DE9: 8 | DF9: $13.00 each? | DG9: aptTrialProc | DH9: aptTrials | DI9: 0 | DJ9: 1 | DK9: 149106 | DL9: 5 | DM9: 149105 | DN9: 51 | DO9: 7000 | DP9: 0 | DR9: 7000 | DS9: -2991 | DT9: 156000 | DU9: 0 | DV9: 156000 | DW9: 2991 | DX9: 152091 | DY9: 4020 | DZ9: 100 | EB9: 0 | EC9: 0 | ED9: 152036 | EE9: 156000 | EF9: 149100 | EG9: 8
A10: R01_NE_APT Run 1_Penultimate Prices EP3_Mar22 | B10: XXXX | C10: 1 | D10: <?xml version="1.0"?>\n<Clock xmlns:dt="urn:schemas-microsoft-com:datatypes"><Description dt:dt="string">E-Prime Primary Realtime Clock</Description><StartTime><Timestamp dt:dt="int">0</Timestamp><DateUtc dt:dt="string">2019-07-05T13:15:01Z</DateUtc></StartTime><FrequencyChanges><FrequencyChange><Frequency dt:dt="r8">2531445</Frequency><Timestamp dt:dt="r8">12159273989</Timestamp><Current dt:dt="r8">0</Current><DateUtc dt:dt="string">2019-07-05T13:15:01Z</DateUtc></FrequencyChange></FrequencyChanges></Clock>\n | E10: R01_NE_APT Run 1_Penultimate Prices EP3_Mar22-01002-1 | F10: 59.956 | G10: 1.0.0.107 | H10: 1 | I10: 6000 | J10: -57 | K10: 0 | L10: 24000 | M10: 57 | N10: 18157 | O10: 5954 | Q10: 0 | R10: 0 | S10: -725311415 | T10: Full | U10: 3.0.3.80 | V10: 3.0.3.80 | W10: 5/7/2019 | X10: 7/5/2019 13:15 | Y10: 0.38542824 | Z10: 3.0.3.82 | AA10: Keyboard | AB10: -1 | AC10: -999999 | AD10: 18100 | AE10: 41 | AF10: 6999 | AG10: 0 | AH10: 5 | AI10: 11101 | AJ10: 18100 | AK10: 9 | AL10: 9 | AM10: 1 | AN10: 9 | AO10: 0 | AP10: ? | AQ10: 4000 | AR10: 0 | AT10: 4000 | AU10: 0 | AV10: 168000 | AW10: 0 | AX10: 168000 | AY10: 0 | AZ10: 164100 | BA10: 4003 | BB10: 100 | BD10: 0 | BE10: 0 | BF10: 164005 | BG10: 168000 | BH10: 164100 | BI10: 7000 | BJ10: 0 | BL10: Keyboard | BM10: 7000 | BN10: -999999 | BO10: 171415 | BP10: 171415 | BQ10: 49 | BR10: 171072 | BS10: 0 | BT10: 100 | BU10: 1 | BV10: 343 | BW10: 171415 | BX10: 171027 | BY10: 177923 | BZ10: 171023 | CA10: 10000 | CB10: 0 | CD10: 10000 | CE10: -8 | CF10: 185000 | CG10: 0 | CH10: 185000 | CI10: 8 | CJ10: 175108 | CK10: 0 | CL10: 100 | CN10: 0 | CO10: 0 | CP10: 175000 | CQ10: 185000 | CR10: 175100 | CS10: 15 | CT10: 4 | CU10: 0 | CV10: 9 | CW10: 10 | CX10: 1 | CY10: 2 | CZ10: 3 | DA10: 4 | DB10: 5 | DC10: 6 | DD10: 7 | DE10: 8 | DF10: $80.00 each? | DG10: aptTrialProc | DH10: aptTrials | DI10: 0 | DJ10: 0 | DK10: 168103 | DL10: 3 | DM10: 168103 | DN10: 50 | DO10: 7000 | DP10: 0 | DR10: 7000 | DS10: -3372 | DT10: 175000 | DU10: 0 | DV10: 175000 | DW10: 3372 | DX10: 171472 | DY10: 3636 | DZ10: 100 | EB10: 0 | EC10: 0 | ED10: 171417 | EE10: 175000 | EF10: 168100 | EG10: 9
A11: R01_NE_APT Run 1_Penultimate Prices EP3_Mar22 | B11: XXXX | C11: 1 | D11: <?xml version="1.0"?>\n<Clock xmlns:dt="urn:schemas-microsoft-com:datatypes"><Description dt:dt="string">E-Prime Primary Realtime Clock</Description><StartTime><Timestamp dt:dt="int">0</Timestamp><DateUtc dt:dt="string">2019-07-05T13:15:01Z</DateUtc></StartTime><FrequencyChanges><FrequencyChange><Frequency dt:dt="r8">2531445</Frequency><Timestamp dt:dt="r8">12159273989</Timestamp><Current dt:dt="r8">0</Current><DateUtc dt:dt="string">2019-07-05T13:15:01Z</DateUtc></FrequencyChange></FrequencyChanges></Clock>\n | E11: R01_NE_APT Run 1_Penultimate Prices EP3_Mar22-01002-1 | F11: 59.956 | G11: 1.0.0.107 | H11: 1 | I11: 6000 | J11: -57 | K11: 0 | L11: 24000 | M11: 57 | N11: 18157 | O11: 5954 | Q11: 0 | R11: 0 | S11: -725311415 | T11: Full | U11: 3.0.3.80 | V11: 3.0.3.80 | W11: 5/7/2019 | X11: 7/5/2019 13:15 | Y11: 0.38542824 | Z11: 3.0.3.82 | AA11: Keyboard | AB11: -1 | AC11: -999999 | AD11: 18100 | AE11: 41 | AF11: 6999 | AG11: 0 | AH11: 5 | AI11: 11101 | AJ11: 18100 | AK11: 10 | AL11: 10 | AM11: 1 | AN11: 10 | AO11: 8 | AP11: ? | AQ11: 4000 | AR11: 0 | AT11: 4000 | AU11: -16 | AV11: 189000 | AW11: 0 | AX11: 189000 | AY11: 16 | AZ11: 185116 | BA11: 3986 | BB11: 100 | BD11: 0 | BE11: 0 | BF11: 185005 | BG11: 189000 | BH11: 185100 | BI11: 7000 | BJ11: 0 | BL11: Keyboard | BM11: 7000 | BN11: -999999 | BO11: 191438 | BP11: 191438 | BQ11: 49 | BR11: 191087 | BS11: 0 | BT11: 100 | BU11: 1 | BV11: 350 | BW11: 191437 | BX11: 191042 | BY11: 197938 | BZ11: 191038 | CA11: 4000 | CB11: 0 | CD11: 4000 | CE11: -8 | CF11: 200000 | CG11: 0 | CH11: 200000 | CI11: 8 | CJ11: 196108 | CK11: 0 | CL11: 100 | CN11: 0 | CO11: 0 | CP11: 196000 | CQ11: 200000 | CR11: 196100 | CS11: 15 | CT11: 4 | CU11: 0 | CV11: 9 | CW11: 10 | CX11: 1 | CY11: 2 | CZ11: 3 | DA11: 4 | DB11: 5 | DC11: 6 | DD11: 7 | DE11: 8 | DF11: $0.01 each? | DG11: aptTrialProc | DH11: aptTrials | DI11: 0 | DJ11: 0 | DK11: 189102 | DL11: 2 | DM11: 189102 | DN11: 50 | DO11: 7000 | DP11: 0 | DR11: 7000 | DS11: -2387 | DT11: 196000 | DU11: 0 | DV11: 196000 | DW11: 2387 | DX11: 191487 | DY11: 4621 | DZ11: 100 | EB11: 0 | EC11: 0 | ED11: 191441 | EE11: 196000 | EF11: 189100 | EG11: 10
A12: R01_NE_APT Run 1_Penultimate Prices EP3_Mar22 | B12: XXXX | C12: 1 | D12: <?xml version="1.0"?>\n<Clock xmlns:dt="urn:schemas-microsoft-com:datatypes"><Description dt:dt="string">E-Prime Primary Realtime Clock</Description><StartTime><Timestamp dt:dt="int">0</Timestamp><DateUtc dt:dt="string">2019-07-05T13:15:01Z</DateUtc></StartTime><FrequencyChanges><FrequencyChange><Frequency dt:dt="r8">2531445</Frequency><Timestamp dt:dt="r8">12159273989</Timestamp><Current dt:dt="r8">0</Current><DateUtc dt:dt="string">2019-07-05T13:15:01Z</DateUtc></FrequencyChange></FrequencyChanges></Clock>\n | E12: R01_NE_APT Run 1_Penultimate Prices EP3_Mar22-01002-1 | F12: 59.956 | G12: 1.0.0.107 | H12: 1 | I12: 6000 | J12: -57 | K12: 0 | L12: 24000 | M12: 57 | N12: 18157 | O12: 5954 | Q12: 0 | R12: 0 | S12: -725311415 | T12: Full | U12: 3.0.3.80 | V12: 3.0.3.80 | W12: 5/7/2019 | X12: 7/5/2019 13:15 | Y12: 0.38542824 | Z12: 3.0.3.82 | AA12: Keyboard | AB12: -1 | AC12: -999999 | AD12: 18100 | AE12: 41 | AF12: 6999 | AG12: 0 | AH12: 5 | AI12: 11101 | AJ12: 18100 | AK12: 11 | AL12: 11 | AM12: 1 | AN12: 11 | AO12: 0 | AP12: ? | AQ12: 4000 | AR12: 0 | AT12: 4000 | AU12: -11 | AV12: 204000 | AW12: 0 | AX12: 204000 | AY12: 11 | AZ12: 200111 | BA12: 4003 | BB12: 100 | BD12: 0 | BE12: 0 | BF12: 200005 | BG12: 204000 | BH12: 200100 | BI12: 7000 | BJ12: 0 | BL12: Keyboard | BM12: 7000 | BN12: -999999 | BO12: 207596 | BP12: 207596 | BQ12: 46 | BR12: 207266 | BS12: 0 | BT12: 100 | BU12: 1 | BV12: 330 | BW12: 207596 | BX12: 207224 | BY12: 214120 | BZ12: 207220 | CA12: 4000 | CB12: 0 | CD12: 4000 | CE12: -2 | CF12: 215000 | CG12: 0 | CH12: 215000 | CI12: 2 | CJ12: 211102 | CK12: 0 | CL12: 100 | CN12: 0 | CO12: 0 | CP12: 211000 | CQ12: 215000 | CR12: 211100 | CS12: 15 | CT12: 4 | CU12: 0 | CV12: 9 | CW12: 10 | CX12: 1 | CY12: 2 | CZ12: 3 | DA12: 4 | DB12: 5 | DC12: 6 | DD12: 7 | DE12: 8 | DF12: $30.00 each? | DG12: aptTrialProc | DH12: aptTrials | DI12: 0 | DJ12: 0 | DK12: 204114 | DL12: 14 | DM12: 204114 | DN12: 50 | DO12: 7000 | DP12: 0 | DR12: 7000 | DS12: -3550 | DT12: 211000 | DU12: 0 | DV12: 211000 | DW12: 3550 | DX12: 207650 | DY12: 3452 | DZ12: 100 | EB12: 0 | EC12: 0 | ED12: 207600 | EE12: 211000 | EF12: 204100 | EG12: 11
A13: R01_NE_APT Run 1_Penultimate Prices EP3_Mar22 | B13: XXXX | C13: 1 | D13: <?xml version="1.0"?>\n<Clock xmlns:dt="urn:schemas-microsoft-com:datatypes"><Description dt:dt="string">E-Prime Primary Realtime Clock</Description><StartTime><Timestamp dt:dt="int">0</Timestamp><DateUtc dt:dt="string">2019-07-05T13:15:01Z</DateUtc></StartTime><FrequencyChanges><FrequencyChange><Frequency dt:dt="r8">2531445</Frequency><Timestamp dt:dt="r8">12159273989</Timestamp><Current dt:dt="r8">0</Current><DateUtc dt:dt="string">2019-07-05T13:15:01Z</DateUtc></FrequencyChange></FrequencyChanges></Clock>\n | E13: R01_NE_APT Run 1_Penultimate Prices EP3_Mar22-01002-1 | F13: 59.956 | G13: 1.0.0.107 | H13: 1 | I13: 6000 | J13: -57 | K13: 0 | L13: 24000 | M13: 57 | N13: 18157 | O13: 5954 | Q13: 0 | R13: 0 | S13: -725311415 | T13: Full | U13: 3.0.3.80 | V13: 3.0.3.80 | W13: 5/7/2019 | X13: 7/5/2019 13:15 | Y13: 0.38542824 | Z13: 3.0.3.82 | AA13: Keyboard | AB13: -1 | AC13: -999999 | AD13: 18100 | AE13: 41 | AF13: 6999 | AG13: 0 | AH13: 5 | AI13: 11101 | AJ13: 18100 | AK13: 12 | AL13: 12 | AM13: 1 | AN13: 12 | AO13: 8 | AP13: ? | AQ13: 4000 | AR13: 0 | AT13: 4000 | AU13: -5 | AV13: 219000 | AW13: 0 | AX13: 219000 | AY13: 5 | AZ13: 215105 | BA13: 4003 | BB13: 100 | BD13: 0 | BE13: 0 | BF13: 215005 | BG13: 219000 | BH13: 215100 | BI13: 7000 | BJ13: 0 | BL13: Keyboard | BM13: 7000 | BN13: -999999 | BO13: 221339 | BP13: 221339 | BQ13: 63 | BR13: 221026 | BS13: 0 | BT13: 100 | BU13: 1 | BV13: 313 | BW13: 221339 | BX13: 220967 | BY13: 227863 | BZ13: 220963 | CA13: 2000 | CB13: 0 | CD13: 2000 | CE13: -14 | CF13: 228000 | CG13: 0 | CH13: 228000 | CI13: 14 | CJ13: 226114 | CK13: 0 | CL13: 100 | CN13: 0 | CO13: 0 | CP13: 226000 | CQ13: 228000 | CR13: 226100 | CS13: 15 | CT13: 4 | CU13: 0 | CV13: 9 | CW13: 10 | CX13: 1 | CY13: 2 | CZ13: 3 | DA13: 4 | DB13: 5 | DC13: 6 | DD13: 7 | DE13: 8 | DF13: $0.02 each? | DG13: aptTrialProc | DH13: aptTrials | DI13: 0 | DJ13: 0 | DK13: 219108 | DL13: 8 | DM13: 219108 | DN13: 50 | DO13: 7000 | DP13: 0 | DR13: 7000 | DS13: -2293 | DT13: 226000 | DU13: 0 | DV13: 226000 | DW13: 2293 | DX13: 221393 | DY13: 4721 | DZ13: 100 | EB13: 0 | EC13: 0 | ED13: 221341 | EE13: 226000 | EF13: 219100 | EG13: 12
... A31: R01_NE_APT Run 1_Penultimate Prices EP3_Mar22 | B31: XXXX | C31: 1 | D31: <?xml version="1.0"?>\n<Clock xmlns:dt="urn:schemas-microsoft-com:datatypes"><Description dt:dt="string">E-Prime Primary Realtime Clock</Description><StartTime><Timestamp dt:dt="int">0</Timestamp><DateUtc dt:dt="string">2019-07-05T13:15:01Z</DateUtc></StartTime><FrequencyChanges><FrequencyChange><Frequency dt:dt="r8">2531445</Frequency><Timestamp dt:dt="r8">12159273989</Timestamp><Current dt:dt="r8">0</Current><DateUtc dt:dt="string">2019-07-05T13:15:01Z</DateUtc></FrequencyChange></FrequencyChanges></Clock>\n | E31: R01_NE_APT Run 1_Penultimate Prices EP3_Mar22-01002-1 | F31: 59.956 | G31: 1.0.0.107 | H31: 1 | I31: 6000 | J31: -57 | K31: 0 | L31: 24000 | M31: 57 | N31: 18157 | O31: 5954 | Q31: 0 | R31: 0 | S31: -725311415 | T31: Full | U31: 3.0.3.80 | V31: 3.0.3.80 | W31: 5/7/2019 | X31: 7/5/2019 13:15 | Y31: 0.38542824 | Z31: 3.0.3.82 | AA31: Keyboard | AB31: -1 | AC31: -999999 | AD31: 18100 | AE31: 41 | AF31: 6999 | AG31: 0 | AH31: 5 | AI31: 11101 | AJ31: 18100 | AK31: 30 | AL31: 30 | AM31: 1 | AN31: 30 | AO31: 3 | AP31: ? | AQ31: 4000 | AR31: 0 | AT31: 4000 | AU31: -9 | AV31: 511000 | AW31: 0 | AX31: 511000 | AY31: 9 | AZ31: 507109 | BA31: 4003 | BB31: 100 | BD31: 0 | BE31: 0 | BF31: 507005 | BG31: 511000 | BH31: 507100 | BI31: 7000 | BJ31: 0 | BL31: Keyboard | BM31: 7000 | BN31: -999999 | BO31: 515613 | BP31: 515613 | BQ31: 59 | BR31: 514264 | BS31: 0 | BT31: 100 | BU31: 1 | BV31: 1348 | BW31: 515612 | BX31: 514209 | BY31: 521105 | BZ31: 514205 | CA31: 4000 | CB31: 0 | CD31: 4000 | CE31: 0 | CF31: 522000 | CG31: 0 | CH31: 522000 | CI31: 0 | CJ31: 518100 | CK31: 0 | CL31: 100 | CN31: 0 | CO31: 0 | CP31: 518000 | CQ31: 522000 | CR31: 518100 | CS31: 15 | CT31: 4 | CU31: 0 | CV31: 9 | CW31: 10 | CX31: 1 | CY31: 2 | CZ31: 3 | DA31: 4 | DB31: 5 | DC31: 6 | DD31: 7 | DE31: 8 | DF31: $15.00 each? | DG31: aptTrialProc | DH31: aptTrials | DI31: 0 | DJ31: 0 | DK31: 511112 | DL31: 12 | DM31: 511112 | DN31: 50 | DO31: 7000 | DP31: 0 | DR31: 7000 | DS31: -4565 | DT31: 518000 | DU31: 0 | DV31: 518000 | DW31: 4565 | DX31: 515665 | DY31: 2435 | DZ31: 100 | EB31: 0 | EC31: 0 | ED31: 515615 | EE31: 518000 | EF31: 511100 | EG31: 30

Sheet Paste Run 2
A1: ExperimentName | B1: Subject | C1: Session | D1: Clock.Information | E1: DataFile.Basename | F1: Display.RefreshRate | G1: ExperimentVersion | H1: Group | I1: Instructions.Duration | J1: Instructions.DurationError | K1: Instructions.OffsetDelay | L1: Instructions.OffsetTime | M1: Instructions.OnsetDelay | N1: Instructions.OnsetTime | O1: Instructions.OnsetToOnsetTime | P1: Instructions.RESP | Q1: Instructions.RT | R1: Instructions.RTTime | S1: RandomSeed | T1: RuntimeCapabilities | U1: RuntimeVersion | V1: RuntimeVersionExpected | W1: SessionDate | X1: SessionStartDateTimeUtc | Y1: SessionTime | Z1: StudioVersion | AA1: Trigger.DEVICE | AB1: Trigger.Duration | AC1: Trigger.DurationError | AD1: Trigger.OffsetTime | AE1: Trigger.OnsetDelay | AF1: Trigger.OnsetTime | AG1: Trigger.OnsetToOnsetTime | AH1: Trigger.RESP | AI1: Trigger.RT | AJ1: Trigger.RTTime | AK1: Block | AL1: aptTrials | AM1: aptTrials.Cycle | AN1: aptTrials.Sample | AO1: Choice | AP1: currentChoice | AQ1: decideduration | AR1: decideNew.ACC | AS1: decideNew.CRESP | AT1: decideNew.Duration | AU1: decideNew.DurationError | AV1: decideNew.FinishTime | AW1: decideNew.OffsetDelay | AX1: decideNew.OffsetTime | AY1: decideNew.OnsetDelay | AZ1: decideNew.OnsetTime | BA1: decideNew.OnsetToOnsetTime | BB1: decideNew.PreRelease | BC1: decideNew.RESP | BD1: decideNew.RT | BE1: decideNew.RTTime | BF1: decideNew.StartTime | BG1: decideNew.TargetOffsetTime | BH1: decideNew.TargetOnsetTime | BI1: inputduration | BJ1: inputresponse.ACC | BK1: inputresponse.CRESP | BL1: inputresponse.DEVICE | BM1: inputresponse.Duration | BN1: inputresponse.DurationError | BO1: inputresponse.FinishTime | BP1: inputresponse.OffsetTime | BQ1: inputresponse.OnsetDelay | BR1: inputresponse.OnsetTime | BS1: inputresponse.OnsetToOnsetTime | BT1: inputresponse.PreRelease | BU1: inputresponse.RESP | BV1: inputresponse.RT | BW1: inputresponse.RTTime | BX1: inputresponse.StartTime | BY1: inputresponse.TargetOffsetTime | BZ1: inputresponse.TargetOnsetTime | CA1: ISI | CB1: ISI.ACC | CC1: ISI.CRESP | CD1: ISI.Duration | CE1: ISI.DurationError | CF1: ISI.FinishTime | CG1: ISI.OffsetDelay | CH1: ISI.OffsetTime | CI1: ISI.OnsetDelay | CJ1: ISI.OnsetTime | CK1: ISI.OnsetToOnsetTime | CL1: ISI.PreRelease | CM1: ISI.RESP | CN1: ISI.RT | CO1: ISI.RTTime | CP1: ISI.StartTime | CQ1: ISI.TargetOffsetTime | CR1: ISI.TargetOnsetTime | CS1: maxpos | CT1: minpos | CU1: pos1 | CV1: pos10 | CW1: pos11 | CX1: pos2 | CY1: pos3 | CZ1: pos4 | DA1: pos5 | DB1: pos6 | DC1: pos7 | DD1: pos8 | DE1: pos9 | DF1: price | DG1: Procedure | DH1: Running | DI1: start.Duration | DJ1: start.DurationError | DK1: start.OffsetTime | DL1: start.OnsetDelay | DM1: start.OnsetTime | DN1: start.OnsetToOnsetTime | DO1: submitduration | DP1: submitted.ACC | DQ1: submitted.CRESP | DR1: submitted.Duration | DS1: submitted.DurationError | DT1: submitted.FinishTime | DU1: submitted.OffsetDelay | DV1: submitted.OffsetTime | DW1: submitted.OnsetDelay | DX1: submitted.OnsetTime | DY1: submitted.OnsetToOnsetTime | DZ1: submitted.PreRelease | EA1: submitted.RESP | EB1: submitted.RT | EC1: submitted.RTTime | ED1: submitted.StartTime | EE1: submitted.TargetOffsetTime | EF1: submitted.TargetOnsetTime | EG1: trialnumber
A2: R01_NE_APT Run 2_Penultimate Prices EP3_Mar22 | B2: XXXX | C2: 1 | D2: <?xml version="1.0"?>\n<Clock xmlns:dt="urn:schemas-microsoft-com:datatypes"><Description dt:dt="string">E-Prime Primary Realtime Clock</Description><StartTime><Timestamp dt:dt="int">0</Timestamp><DateUtc dt:dt="string">2019-07-05T13:24:23Z</DateUtc></StartTime><FrequencyChanges><FrequencyChange><Frequency dt:dt="r8">2531445</Frequency><Timestamp dt:dt="r8">13581237373</Timestamp><Current dt:dt="r8">0</Current><DateUtc dt:dt="string">2019-07-05T13:24:23Z</DateUtc></FrequencyChange></FrequencyChanges></Clock>\n | E2: R01_NE_APT Run 2_Penultimate Prices EP3_Mar22-01002-1 | F2: 59.963 | G2: 1.0.0.105 | H2: 1 | I2: 6000 | J2: -41 | K2: 0 | L2: 24369 | M2: 41 | N2: 18510 | O2: 5971 | Q2: 0 | R2: 0 | S2: 696637077 | T2: Full | U2: 3.0.3.80 | V2: 3.0.3.80 | W2: 5/7/2019 | X2: 7/5/2019 13:24 | Y2: 0.39193287 | Z2: 3.0.3.82 | AA2: Keyboard | AB2: -1 | AC2: -999999 | AD2: 18469 | AE2: 39 | AF2: 5767 | AG2: 0 | AH2: 5 | AI2: 12702 | AJ2: 18469 | AK2: 1 | AL2: 1 | AM2: 1 | AN2: 1 | AO2: 8 | AP2: ? | AQ2: 4000 | AR2: 0 | AT2: 4000 | AU2: -12 | AV2: 28369 | AW2: 0 | AX2: 28369 | AY2: 12 | AZ2: 24481 | BA2: 4004 | BB2: 100 | BD2: 0 | BE2: 0 | BF2: 24371 | BG2: 28369 | BH2: 24469 | BI2: 7000 | BJ2: 0 | BL2: Keyboard | BM2: 7000 | BN2: -999999 | BO2: 31303 | BP2: 31303 | BQ2: 51 | BR2: 30586 | BS2: 0 | BT2: 100 | BU2: 1 | BV2: 716 | BW2: 31302 | BX2: 30538 | BY2: 37435 | BZ2: 30535 | CA2: 6000 | CB2: 0 | CD2: 6000 | CE2: -4 | CF2: 41369 | CG2: 0 | CH2: 41369 | CI2: 4 | CJ2: 35473 | CK2: 0 | CL2: 100 | CN2: 0 | CO2: 0 | CP2: 35369 | CQ2: 41369 | CR2: 35469 | CS2: 15 | CT2: 4 | CU2: 0 | CV2: 9 | CW2: 10 | CX2: 1 | CY2: 2 | CZ2: 3 | DA2: 4 | DB2: 5 | DC2: 6 | DD2: 7 | DE2: 8 | DF2: $0.03 each? | DG2: aptTrialProc | DH2: aptTrials | DI2: 0 | DJ2: 0 | DK2: 28485 | DL2: 16 | DM2: 28485 | DN2: 66 | DO2: 7000 | DP2: 0 | DR2: 7000 | DS2: -2884 | DT2: 35369 | DU2: 0 | DV2: 35369 | DW2: 2884 | DX2: 31353 | DY2: 4120 | DZ2: 100 | EB2: 0 | EC2: 0 | ED2: 31305 | EE2: 35369 | EF2: 28469 | EG2: 1
A3: R01_NE_APT Run 2_Penultimate Prices EP3_Mar22 | B3: XXXX | C3: 1 | D3: <?xml version="1.0"?>\n<Clock xmlns:dt="urn:schemas-microsoft-com:datatypes"><Description dt:dt="string">E-Prime Primary Realtime Clock</Description><StartTime><Timestamp dt:dt="int">0</Timestamp><DateUtc dt:dt="string">2019-07-05T13:24:23Z</DateUtc></StartTime><FrequencyChanges><FrequencyChange><Frequency dt:dt="r8">2531445</Frequency><Timestamp dt:dt="r8">13581237373</Timestamp><Current dt:dt="r8">0</Current><DateUtc dt:dt="string">2019-07-05T13:24:23Z</DateUtc></FrequencyChange></FrequencyChanges></Clock>\n | E3: R01_NE_APT Run 2_Penultimate Prices EP3_Mar22-01002-1 | F3: 59.963 | G3: 1.0.0.105 | H3: 1 | I3: 6000 | J3: -41 | K3: 0 | L3: 24369 | M3: 41 | N3: 18510 | O3: 5971 | Q3: 0 | R3: 0 | S3: 696637077 | T3: Full | U3: 3.0.3.80 | V3: 3.0.3.80 | W3: 5/7/2019 | X3: 7/5/2019 13:24 | Y3: 0.39193287 | Z3: 3.0.3.82 | AA3: Keyboard | AB3: -1 | AC3: -999999 | AD3: 18469 | AE3: 39 | AF3: 5767 | AG3: 0 | AH3: 5 | AI3: 12702 | AJ3: 18469 | AK3: 2 | AL3: 2 | AM3: 1 | AN3: 2 | AO3: 7 | AP3: ? | AQ3: 4000 | AR3: 0 | AT3: 4000 | AU3: -9 | AV3: 45369 | AW3: 0 | AX3: 45369 | AY3: 9 | AZ3: 41478 | BA3: 4003 | BB3: 100 | BD3: 0 | BE3: 0 | BF3: 41374 | BG3: 45369 | BH3: 41469 | BI3: 7000 | BJ3: 0 | BL3: Keyboard | BM3: 7000 | BN3: -999999 | BO3: 47782 | BP3: 47781 | BQ3: 48 | BR3: 47365 | BS3: 0 | BT3: 100 | BU3: 1 | BV3: 416 | BW3: 47781 | BX3: 47321 | BY3: 54217 | BZ3: 47317 | CA3: 12000 | CB3: 0 | CD3: 12000 | CE3: 0 | CF3: 64369 | CG3: 0 | CH3: 64369 | CI3: 0 | CJ3: 52469 | CK3: 0 | CL3: 100 | CN3: 0 | CO3: 0 | CP3: 52369 | CQ3: 64369 | CR3: 52469 | CS3: 15 | CT3: 4 | CU3: 0 | CV3: 9 | CW3: 10 | CX3: 1 | CY3: 2 | CZ3: 3 | DA3: 4 | DB3: 5 | DC3: 6 | DD3: 7 | DE3: 8 | DF3: $5.00 each? | DG3: aptTrialProc | DH3: aptTrials | DI3: 0 | DJ3: 0 | DK3: 45481 | DL3: 12 | DM3: 45481 | DN3: 50 | DO3: 7000 | DP3: 0 | DR3: 7000 | DS3: -2363 | DT3: 52369 | DU3: 0 | DV3: 52369 | DW3: 2363 | DX3: 47832 | DY3: 4637 | DZ3: 100 | EB3: 0 | EC3: 0 | ED3: 47783 | EE3: 52369 | EF3: 45469 | EG3: 2
A4: R01_NE_APT Run 2_Penultimate Prices EP3_Mar22 | B4: XXXX | C4: 1 | D4: <?xml version="1.0"?>\n<Clock xmlns:dt="urn:schemas-microsoft-com:datatypes"><Description dt:dt="string">E-Prime Primary Realtime Clock</Description><StartTime><Timestamp dt:dt="int">0</Timestamp><DateUtc dt:dt="string">2019-07-05T13:24:23Z</DateUtc></StartTime><FrequencyChanges><FrequencyChange><Frequency dt:dt="r8">2531445</Frequency><Timestamp dt:dt="r8">13581237373</Timestamp><Current dt:dt="r8">0</Current><DateUtc dt:dt="string">2019-07-05T13:24:23Z</DateUtc></FrequencyChange></FrequencyChanges></Clock>\n | E4: R01_NE_APT Run 2_Penultimate Prices EP3_Mar22-01002-1 | F4: 59.963 | G4: 1.0.0.105 | H4: 1 | I4: 6000 | J4: -41 | K4: 0 | L4: 24369 | M4: 41 | N4: 18510 | O4: 5971 | Q4: 0 | R4: 0 | S4: 696637077 | T4: Full | U4: 3.0.3.80 | V4: 3.0.3.80 | W4: 5/7/2019 | X4: 7/5/2019 13:24 | Y4: 0.39193287 | Z4: 3.0.3.82 | AA4: Keyboard | AB4: -1 | AC4: -999999 | AD4: 18469 | AE4: 39 | AF4: 5767 | AG4: 0 | AH4: 5 | AI4: 12702 | AJ4: 18469 | AK4: 3 | AL4: 3 | AM4: 1 | AN4: 3 | AO4: 0 | AP4: ? | AQ4: 4000 | AR4: 0 | AT4: 4000 | AU4: -9 | AV4: 68369 | AW4: 0 | AX4: 68369 | AY4: 9 | AZ4: 64478 | BA4: 4003 | BB4: 100 | BD4: 0 | BE4: 0 | BF4: 64374 | BG4: 68369 | BH4: 64469 | BI4: 7000 | BJ4: 0 | BL4: Keyboard | BM4: 7000 | BN4: -999999 | BO4: 70996 | BP4: 70996 | BQ4: 62 | BR4: 70666 | BS4: 0 | BT4: 100 | BU4: 1 | BV4: 329 | BW4: 70995 | BX4: 70608 | BY4: 77504 | BZ4: 70604 | CA4: 8000 | CB4: 0 | CD4: 8000 | CE4: -1 | CF4: 83369 | CG4: 0 | CH4: 83369 | CI4: 1 | CJ4: 75470 | CK4: 0 | CL4: 100 | CN4: 0 | CO4: 0 | CP4: 75369 | CQ4: 83369 | CR4: 75469 | CS4: 15 | CT4: 4 | CU4: 0 | CV4: 9 | CW4: 10 | CX4: 1 | CY4: 2 | CZ4: 3 | DA4: 4 | DB4: 5 | DC4: 6 | DD4: 7 | DE4: 8 | DF4: $80.00 each? | DG4: aptTrialProc | DH4: aptTrials | DI4: 0 | DJ4: 0 | DK4: 68481 | DL4: 12 | DM4: 68481 | DN4: 67 | DO4: 7000 | DP4: 0 | DR4: 7000 | DS4: -2581 | DT4: 75369 | DU4: 0 | DV4: 75369 | DW4: 2581 | DX4: 71050 | DY4: 4420 | DZ4: 100 | EB4: 0 | EC4: 0 | ED4: 70999 | EE4: 75369 | EF4: 68469 | EG4: 3
A5: R01_NE_APT Run 2_Penultimate Prices EP3_Mar22 | B5: XXXX | C5: 1 | D5: <?xml version="1.0"?>\n<Clock xmlns:dt="urn:schemas-microsoft-com:datatypes"><Description dt:dt="string">E-Prime Primary Realtime Clock</Description><StartTime><Timestamp dt:dt="int">0</Timestamp><DateUtc dt:dt="string">2019-07-05T13:24:23Z</DateUtc></StartTime><FrequencyChanges><FrequencyChange><Frequency dt:dt="r8">2531445</Frequency><Timestamp dt:dt="r8">13581237373</Timestamp><Current dt:dt="r8">0</Current><DateUtc dt:dt="string">2019-07-05T13:24:23Z</DateUtc></FrequencyChange></FrequencyChanges></Clock>\n | E5: R01_NE_APT Run 2_Penultimate Prices EP3_Mar22-01002-1 | F5: 59.963 | G5: 1.0.0.105 | H5: 1 | I5: 6000 | J5: -41 | K5: 0 | L5: 24369 | M5: 41 | N5: 18510 | O5: 5971 | Q5: 0 | R5: 0 | S5: 696637077 | T5: Full | U5: 3.0.3.80 | V5: 3.0.3.80 | W5: 5/7/2019 | X5: 7/5/2019 13:24 | Y5: 0.39193287 | Z5: 3.0.3.82 | AA5: Keyboard | AB5: -1 | AC5: -999999 | AD5: 18469 | AE5: 39 | AF5: 5767 | AG5: 0 | AH5: 5 | AI5: 12702 | AJ5: 18469 | AK5: 4 | AL5: 4 | AM5: 1 | AN5: 4 | AO5: 8 | AP5: ? | AQ5: 4000 | AR5: 0 | AT5: 4000 | AU5: -7 | AV5: 87369 | AW5: 0 | AX5: 87369 | AY5: 7 | AZ5: 83476 | BA5: 4003 | BB5: 100 | BD5: 0 | BE5: 0 | BF5: 83374 | BG5: 87369 | BH5: 83469 | BI5: 7000 | BJ5: 0 | BL5: Keyboard | BM5: 7000 | BN5: -999999 | BO5: 90010 | BP5: 90010 | BQ5: 52 | BR5: 89430 | BS5: 0 | BT5: 100 | BU5: 1 | BV5: 580 | BW5: 90010 | BX5: 89382 | BY5: 96278 | BZ5: 89378 | CA5: 4000 | CB5: 0 | CD5: 4000 | CE5: -15 | CF5: 98369 | CG5: 0 | CH5: 98369 | CI5: 15 | CJ5: 94484 | CK5: 0 | CL5: 100 | CN5: 0 | CO5: 0 | CP5: 94369 | CQ5: 98369 | CR5: 94469 | CS5: 15 | CT5: 4 | CU5: 0 | CV5: 9 | CW5: 10 | CX5: 1 | CY5: 2 | CZ5: 3 | DA5: 4 | DB5: 5 | DC5: 6 | DD5: 7 | DE5: 8 | DF5: $0.01 each? | DG5: aptTrialProc | DH5: aptTrials | DI5: 0 | DJ5: 0 | DK5: 87479 | DL5: 10 | DM5: 87479 | DN5: 50 | DO5: 7000 | DP5: 0 | DR5: 7000 | DS5: -2595 | DT5: 94369 | DU5: 0 | DV5: 94369 | DW5: 2595 | DX5: 90064 | DY5: 4420 | DZ5: 100 | EB5: 0 | EC5: 0 | ED5: 90012 | EE5: 94369 | EF5: 87469 | EG5: 4
A6: R01_NE_APT Run 2_Penultimate Prices EP3_Mar22 | B6: XXXX | C6: 1 | D6: <?xml version="1.0"?>\n<Clock xmlns:dt="urn:schemas-microsoft-com:datatypes"><Description dt:dt="string">E-Prime Primary Realtime Clock</Description><StartTime><Timestamp dt:dt="int">0</Timestamp><DateUtc dt:dt="string">2019-07-05T13:24:23Z</DateUtc></StartTime><FrequencyChanges><FrequencyChange><Frequency dt:dt="r8">2531445</Frequency><Timestamp dt:dt="r8">13581237373</Timestamp><Current dt:dt="r8">0</Current><DateUtc dt:dt="string">2019-07-05T13:24:23Z</DateUtc></FrequencyChange></FrequencyChanges></Clock>\n | E6: R01_NE_APT Run 2_Penultimate Prices EP3_Mar22-01002-1 | F6: 59.963 | G6: 1.0.0.105 | H6: 1 | I6: 6000 | J6: -41 | K6: 0 | L6: 24369 | M6: 41 | N6: 18510 | O6: 5971 | Q6: 0 | R6: 0 | S6: 696637077 | T6: Full | U6: 3.0.3.80 | V6: 3.0.3.80 | W6: 5/7/2019 | X6: 7/5/2019 13:24 | Y6: 0.39193287 | Z6: 3.0.3.82 | AA6: Keyboard | AB6: -1 | AC6: -999999 | AD6: 18469 | AE6: 39 | AF6: 5767 | AG6: 0 | AH6: 5 | AI6: 12702 | AJ6: 18469 | AK6: 5 | AL6: 5 | AM6: 1 | AN6: 5 | AO6: 5 | AP6: ? | AQ6: 4000 | AR6: 0 | AT6: 4000 | AU6: -1 | AV6: 102369 | AW6: 0 | AX6: 102369 | AY6: 1 | AZ6: 98470 | BA6: 4003 | BB6: 100 | BD6: 0 | BE6: 0 | BF6: 98374 | BG6: 102369 | BH6: 98469 | BI6: 7000 | BJ6: 0 | BL6: Keyboard | BM6: 7000 | BN6: -999999 | BO6: 104089 | BP6: 104089 | BQ6: 49 | BR6: 103458 | BS6: 0 | BT6: 100 | BU6: 1 | BV6: 631 | BW6: 104089 | BX6: 103413 | BY6: 110309 | BZ6: 103409 | CA6: 4000 | CB6: 0 | CD6: 4000 | CE6: -10 | CF6: 113369 | CG6: 0 | CH6: 113369 | CI6: 10 | CJ6: 109479 | CK6: 0 | CL6: 100 | CN6: 0 | CO6: 0 | CP6: 109369 | CQ6: 113369 | CR6: 109469 | CS6: 15 | CT6: 4 | CU6: 0 | CV6: 9 | CW6: 10 | CX6: 1 | CY6: 2 | CZ6: 3 | DA6: 4 | DB6: 5 | DC6: 6 | DD6: 7 | DE6: 8 | DF6: $7.00 each? | DG6: aptTrialProc | DH6: aptTrials | DI6: 0 | DJ6: 1 | DK6: 102474 | DL6: 4 | DM6: 102473 | DN6: 51 | DO6: 7000 | DP6: 0 | DR6: 7000 | DS6: -1673 | DT6: 109369 | DU6: 0 | DV6: 109369 | DW6: 1673 | DX6: 104142 | DY6: 5337 | DZ6: 100 | EB6: 0 | EC6: 0 | ED6: 104092 | EE6: 109369 | EF6: 102469 | EG6: 5
A7: R01_NE_APT Run 2_Penultimate Prices EP3_Mar22 | B7: XXXX | C7: 1 | D7: <?xml version="1.0"?>\n<Clock xmlns:dt="urn:schemas-microsoft-com:datatypes"><Description dt:dt="string">E-Prime Primary Realtime Clock</Description><StartTime><Timestamp dt:dt="int">0</Timestamp><DateUtc dt:dt="string">2019-07-05T13:24:23Z</DateUtc></StartTime><FrequencyChanges><FrequencyChange><Frequency dt:dt="r8">2531445</Frequency><Timestamp dt:dt="r8">13581237373</Timestamp><Current dt:dt="r8">0</Current><DateUtc dt:dt="string">2019-07-05T13:24:23Z</DateUtc></FrequencyChange></FrequencyChanges></Clock>\n | E7: R01_NE_APT Run 2_Penultimate Prices EP3_Mar22-01002-1 | F7: 59.963 | G7: 1.0.0.105 | H7: 1 | I7: 6000 | J7: -41 | K7: 0 | L7: 24369 | M7: 41 | N7: 18510 | O7: 5971 | Q7: 0 | R7: 0 | S7: 696637077 | T7: Full | U7: 3.0.3.80 | V7: 3.0.3.80 | W7: 5/7/2019 | X7: 7/5/2019 13:24 | Y7: 0.39193287 | Z7: 3.0.3.82 | AA7: Keyboard | AB7: -1 | AC7: -999999 | AD7: 18469 | AE7: 39 | AF7: 5767 | AG7: 0 | AH7: 5 | AI7: 12702 | AJ7: 18469 | AK7: 6 | AL7: 6 | AM7: 1 | AN7: 6 | AO7: 8 | AP7: ? | AQ7: 4000 | AR7: 0 | AT7: 4000 | AU7: -13 | AV7: 117369 | AW7: 0 | AX7: 117369 | AY7: 13 | AZ7: 113482 | BA7: 4003 | BB7: 100 | BD7: 0 | BE7: 0 | BF7: 113374 | BG7: 117369 | BH7: 113469 | BI7: 7000 | BJ7: 0 | BL7: Keyboard | BM7: 7000 | BN7: -999999 | BO7: 119304 | BP7: 119304 | BQ7: 40 | BR7: 118936 | BS7: 0 | BT7: 100 | BU7: 1 | BV7: 368 | BW7: 119304 | BX7: 118900 | BY7: 125796 | BZ7: 118896 | CA7: 2000 | CB7: 0 | CD7: 2000 | CE7: -4 | CF7: 126369 | CG7: 0 | CH7: 126369 | CI7: 4 | CJ7: 124473 | CK7: 0 | CL7: 100 | CN7: 0 | CO7: 0 | CP7: 124369 | CQ7: 126369 | CR7: 124469 | CS7: 15 | CT7: 4 | CU7: 0 | CV7: 9 | CW7: 10 | CX7: 1 | CY7: 2 | CZ7: 3 | DA7: 4 | DB7: 5 | DC7: 6 | DD7: 7 | DE7: 8 | DF7: $0.04 each? | DG7: aptTrialProc | DH7: aptTrials | DI7: 0 | DJ7: 0 | DK7: 117485 | DL7: 16 | DM7: 117485 | DN7: 50 | DO7: 7000 | DP7: 0 | DR7: 7000 | DS7: -1884 | DT7: 124369 | DU7: 0 | DV7: 124369 | DW7: 1884 | DX7: 119353 | DY7: 5120 | DZ7: 100 | EB7: 0 | EC7: 0 | ED7: 119306 | EE7: 124369 | EF7: 117469 | EG7: 6
A8: R01_NE_APT Run 2_Penultimate Prices EP3_Mar22 | B8: XXXX | C8: 1 | D8: <?xml version="1.0"?>\n<Clock xmlns:dt="urn:schemas-microsoft-com:datatypes"><Description dt:dt="string">E-Prime Primary Realtime Clock</Description><StartTime><Timestamp dt:dt="int">0</Timestamp><DateUtc dt:dt="string">2019-07-05T13:24:23Z</DateUtc></StartTime><FrequencyChanges><FrequencyChange><Frequency dt:dt="r8">2531445</Frequency><Timestamp dt:dt="r8">13581237373</Timestamp><Current dt:dt="r8">0</Current><DateUtc dt:dt="string">2019-07-05T13:24:23Z</DateUtc></FrequencyChange></FrequencyChanges></Clock>\n | E8: R01_NE_APT Run 2_Penultimate Prices EP3_Mar22-01002-1 | F8: 59.963 | G8: 1.0.0.105 | H8: 1 | I8: 6000 | J8: -41 | K8: 0 | L8: 24369 | M8: 41 | N8: 18510 | O8: 5971 | Q8: 0 | R8: 0 | S8: 696637077 | T8: Full | U8: 3.0.3.80 | V8: 3.0.3.80 | W8: 5/7/2019 | X8: 7/5/2019 13:24 | Y8: 0.39193287 | Z8: 3.0.3.82 | AA8: Keyboard | AB8: -1 | AC8: -999999 | AD8: 18469 | AE8: 39 | AF8: 5767 | AG8: 0 | AH8: 5 | AI8: 12702 | AJ8: 18469 | AK8: 7 | AL8: 7 | AM8: 1 | AN8: 7 | AO8: 0 | AP8: ? | AQ8: 4000 | AR8: 0 | AT8: 4000 | AU8: -6 | AV8: 130369 | AW8: 0 | AX8: 130369 | AY8: 6 | AZ8: 126475 | BA8: 4003 | BB8: 100 | BD8: 0 | BE8: 0 | BF8: 126374 | BG8: 130369 | BH8: 126469 | BI8: 7000 | BJ8: 0 | BL8: Keyboard | BM8: 7000 | BN8: -999999 | BO8: 134367 | BP8: 134367 | BQ8: 41 | BR8: 134064 | BS8: 0 | BT8: 100 | BU8: 1 | BV8: 303 | BW8: 134367 | BX8: 134026 | BY8: 140923 | BZ8: 134023 | CA8: 8000 | CB8: 0 | CD8: 8000 | CE8: -14 | CF8: 145369 | CG8: 0 | CH8: 145369 | CI8: 14 | CJ8: 137483 | CK8: 0 | CL8: 100 | CN8: 0 | CO8: 0 | CP8: 137369 | CQ8: 145369 | CR8: 137469 | CS8: 15 | CT8: 4 | CU8: 0 | CV8: 9 | CW8: 10 | CX8: 1 | CY8: 2 | CZ8: 3 | DA8: 4 | DB8: 5 | DC8: 6 | DD8: 7 | DE8: 8 | DF8: $50.00 each? | DG8: aptTrialProc | DH8: aptTrials | DI8: 0 | DJ8: 0 | DK8: 130478 | DL8: 9 | DM8: 130478 | DN8: 50 | DO8: 7000 | DP8: 0 | DR8: 7000 | DS8: -3945 | DT8: 137369 | DU8: 0 | DV8: 137369 | DW8: 3945 | DX8: 134414 | DY8: 3069 | DZ8: 100 | EB8: 0 | EC8: 0 | ED8: 134370 | EE8: 137369 | EF8: 130469 | EG8: 7
A9: R01_NE_APT Run 2_Penultimate Prices EP3_Mar22 | B9: XXXX | C9: 1 | D9: <?xml version="1.0"?>\n<Clock xmlns:dt="urn:schemas-microsoft-com:datatypes"><Description dt:dt="string">E-Prime Primary Realtime Clock</Description><StartTime><Timestamp dt:dt="int">0</Timestamp><DateUtc dt:dt="string">2019-07-05T13:24:23Z</DateUtc></StartTime><FrequencyChanges><FrequencyChange><Frequency dt:dt="r8">2531445</Frequency><Timestamp dt:dt="r8">13581237373</Timestamp><Current dt:dt="r8">0</Current><DateUtc dt:dt="string">2019-07-05T13:24:23Z</DateUtc></FrequencyChange></FrequencyChanges></Clock>\n | E9: R01_NE_APT Run 2_Penultimate Prices EP3_Mar22-01002-1 | F9: 59.963 | G9: 1.0.0.105 | H9: 1 | I9: 6000 | J9: -41 | K9: 0 | L9: 24369 | M9: 41 | N9: 18510 | O9: 5971 | Q9: 0 | R9: 0 | S9: 696637077 | T9: Full | U9: 3.0.3.80 | V9: 3.0.3.80 | W9: 5/7/2019 | X9: 7/5/2019 13:24 | Y9: 0.39193287 | Z9: 3.0.3.82 | AA9: Keyboard | AB9: -1 | AC9: -999999 | AD9: 18469 | AE9: 39 | AF9: 5767 | AG9: 0 | AH9: 5 | AI9: 12702 | AJ9: 18469 | AK9: 8 | AL9: 8 | AM9: 1 | AN9: 8 | AO9: 3 | AP9: ? | AQ9: 4000 | AR9: 0 | AT9: 4000 | AU9: -4 | AV9: 149369 | AW9: 0 | AX9: 149369 | AY9: 4 | AZ9: 145473 | BA9: 4003 | BB9: 100 | BD9: 0 | BE9: 0 | BF9: 145374 | BG9: 149369 | BH9: 145469 | BI9: 7000 | BJ9: 0 | BL9: Keyboard | BM9: 7000 | BN9: -999999 | BO9: 151517 | BP9: 151517 | BQ9: 42 | BR9: 151144 | BS9: 0 | BT9: 100 | BU9: 1 | BV9: 373 | BW9: 151517 | BX9: 151106 | BY9: 158002 | BZ9: 151102 | CA9: 8000 | CB9: 0 | CD9: 8000 | CE9: -12 | CF9: 164369 | CG9: 0 | CH9: 164369 | CI9: 12 | CJ9: 156481 | CK9: 0 | CL9: 100 | CN9: 0 | CO9: 0 | CP9: 156369 | CQ9: 164369 | CR9: 156469 | CS9: 15 | CT9: 4 | CU9: 0 | CV9: 9 | CW9: 10 | CX9: 1 | CY9: 2 | CZ9: 3 | DA9: 4 | DB9: 5 | DC9: 6 | DD9: 7 | DE9: 8 | DF9: $15.00 each? | DG9: aptTrialProc | DH9: aptTrials | DI9: 0 | DJ9: 0 | DK9: 149476 | DL9: 7 | DM9: 149476 | DN9: 50 | DO9: 7000 | DP9: 0 | DR9: 7000 | DS9: -2092 | DT9: 156369 | DU9: 0 | DV9: 156369 | DW9: 2092 | DX9: 151561 | DY9: 4920 | DZ9: 100 | EB9: 0 | EC9: 0 | ED9: 151519 | EE9: 156369 | EF9: 149469 | EG9: 8
A10: R01_NE_APT Run 2_Penultimate Prices EP3_Mar22 | B10: XXXX | C10: 1 | D10: <?xml version="1.0"?>\n<Clock xmlns:dt="urn:schemas-microsoft-com:datatypes"><Description dt:dt="string">E-Prime Primary Realtime Clock</Description><StartTime><Timestamp dt:dt="int">0</Timestamp><DateUtc dt:dt="string">2019-07-05T13:24:23Z</DateUtc></StartTime><FrequencyChanges><FrequencyChange><Frequency dt:dt="r8">2531445</Frequency><Timestamp dt:dt="r8">13581237373</Timestamp><Current dt:dt="r8">0</Current><DateUtc dt:dt="string">2019-07-05T13:24:23Z</DateUtc></FrequencyChange></FrequencyChanges></Clock>\n | E10: R01_NE_APT Run 2_Penultimate Prices EP3_Mar22-01002-1 | F10: 59.963 | G10: 1.0.0.105 | H10: 1 | I10: 6000 | J10: -41 | K10: 0 | L10: 24369 | M10: 41 | N10: 18510 | O10: 5971 | Q10: 0 | R10: 0 | S10: 696637077 | T10: Full | U10: 3.0.3.80 | V10: 3.0.3.80 | W10: 5/7/2019 | X10: 7/5/2019 13:24 | Y10: 0.39193287 | Z10: 3.0.3.82 | AA10: Keyboard | AB10: -1 | AC10: -999999 | AD10: 18469 | AE10: 39 | AF10: 5767 | AG10: 0 | AH10: 5 | AI10: 12702 | AJ10: 18469 | AK10: 9 | AL10: 9 | AM10: 1 | AN10: 9 | AO10: 0 | AP10: ? | AQ10: 4000 | AR10: 0 | AT10: 4000 | AU10: -1 | AV10: 168369 | AW10: 0 | AX10: 168369 | AY10: 1 | AZ10: 164470 | BA10: 4003 | BB10: 100 | BD10: 0 | BE10: 0 | BF10: 164374 | BG10: 168369 | BH10: 164469 | BI10: 7000 | BJ10: 0 | BL10: Keyboard | BM10: 7000 | BN10: -999999 | BO10: 170756 | BP10: 170756 | BQ10: 51 | BR10: 170391 | BS10: 0 | BT10: 100 | BU10: 1 | BV10: 365 | BW10: 170756 | BX10: 170344 | BY10: 177240 | BZ10: 170340 | CA10: 10000 | CB10: 0 | CD10: 10000 | CE10: -9 | CF10: 185369 | CG10: 0 | CH10: 185369 | CI10: 9 | CJ10: 175478 | CK10: 0 | CL10: 100 | CN10: 0 | CO10: 0 | CP10: 175369 | CQ10: 185369 | CR10: 175469 | CS10: 15 | CT10: 4 | CU10: 0 | CV10: 9 | CW10: 10 | CX10: 1 | CY10: 2 | CZ10: 3 | DA10: 4 | DB10: 5 | DC10: 6 | DD10: 7 | DE10: 8 | DF10: $50.00 each? | DG10: aptTrialProc | DH10: aptTrials | DI10: 0 | DJ10: 0 | DK10: 168473 | DL10: 4 | DM10: 168473 | DN10: 50 | DO10: 7000 | DP10: 0 | DR10: 7000 | DS10: -2323 | DT10: 175369 | DU10: 0 | DV10: 175369 | DW10: 2323 | DX10: 170792 | DY10: 4686 | DZ10: 100 | EB10: 0 | EC10: 0 | ED10: 170758 | EE10: 175369 | EF10: 168469 | EG10: 9
A11: R01_NE_APT Run 2_Penultimate Prices EP3_Mar22 | B11: XXXX | C11: 1 | D11: <?xml version="1.0"?>\n<Clock xmlns:dt="urn:schemas-microsoft-com:datatypes"><Description dt:dt="string">E-Prime Primary Realtime Clock</Description><StartTime><Timestamp dt:dt="int">0</Timestamp><DateUtc dt:dt="string">2019-07-05T13:24:23Z</DateUtc></StartTime><FrequencyChanges><FrequencyChange><Frequency dt:dt="r8">2531445</Frequency><Timestamp dt:dt="r8">13581237373</Timestamp><Current dt:dt="r8">0</Current><DateUtc dt:dt="string">2019-07-05T13:24:23Z</DateUtc></FrequencyChange></FrequencyChanges></Clock>\n | E11: R01_NE_APT Run 2_Penultimate Prices EP3_Mar22-01002-1 | F11: 59.963 | G11: 1.0.0.105 | H11: 1 | I11: 6000 | J11: -41 | K11: 0 | L11: 24369 | M11: 41 | N11: 18510 | O11: 5971 | Q11: 0 | R11: 0 | S11: 696637077 | T11: Full | U11: 3.0.3.80 | V11: 3.0.3.80 | W11: 5/7/2019 | X11: 7/5/2019 13:24 | Y11: 0.39193287 | Z11: 3.0.3.82 | AA11: Keyboard | AB11: -1 | AC11: -999999 | AD11: 18469 | AE11: 39 | AF11: 5767 | AG11: 0 | AH11: 5 | AI11: 12702 | AJ11: 18469 | AK11: 10 | AL11: 10 | AM11: 1 | AN11: 10 | AO11: 8 | AP11: ? | AQ11: 4000 | AR11: 0 | AT11: 4000 | AU11: 0 | AV11: 189369 | AW11: 0 | AX11: 189369 | AY11: 0 | AZ11: 185469 | BA11: 4003 | BB11: 100 | BD11: 0 | BE11: 0 | BF11: 185374 | BG11: 189369 | BH11: 185469 | BI11: 7000 | BJ11: 0 | BL11: Keyboard | BM11: 7000 | BN11: -999999 | BO11: 191250 | BP11: 191250 | BQ11: 50 | BR11: 190924 | BS11: 0 | BT11: 100 | BU11: 1 | BV11: 326 | BW11: 191250 | BX11: 190880 | BY11: 197774 | BZ11: 190874 | CA11: 4000 | CB11: 0 | CD11: 4000 | CE11: -9 | CF11: 200369 | CG11: 0 | CH11: 200369 | CI11: 9 | CJ11: 196478 | CK11: 0 | CL11: 100 | CN11: 0 | CO11: 0 | CP11: 196369 | CQ11: 200369 | CR11: 196469 | CS11: 15 | CT11: 4 | CU11: 0 | CV11: 9 | CW11: 10 | CX11: 1 | CY11: 2 | CZ11: 3 | DA11: 4 | DB11: 5 | DC11: 6 | DD11: 7 | DE11: 8 | DF11: $0.04 each? | DG11: aptTrialProc | DH11: aptTrials | DI11: 0 | DJ11: 0 | DK11: 189472 | DL11: 3 | DM11: 189472 | DN11: 51 | DO11: 7000 | DP11: 0 | DR11: 7000 | DS11: -1822 | DT11: 196369 | DU11: 0 | DV11: 196369 | DW11: 1822 | DX11: 191291 | DY11: 5187 | DZ11: 100 | EB11: 0 | EC11: 0 | ED11: 191253 | EE11: 196369 | EF11: 189469 | EG11: 10
A12: R01_NE_APT Run 2_Penultimate Prices EP3_Mar22 | B12: XXXX | C12: 1 | D12: <?xml version="1.0"?>\n<Clock xmlns:dt="urn:schemas-microsoft-com:datatypes"><Description dt:dt="string">E-Prime Primary Realtime Clock</Description><StartTime><Timestamp dt:dt="int">0</Timestamp><DateUtc dt:dt="string">2019-07-05T13:24:23Z</DateUtc></StartTime><FrequencyChanges><FrequencyChange><Frequency dt:dt="r8">2531445</Frequency><Timestamp dt:dt="r8">13581237373</Timestamp><Current dt:dt="r8">0</Current><DateUtc dt:dt="string">2019-07-05T13:24:23Z</DateUtc></FrequencyChange></FrequencyChanges></Clock>\n | E12: R01_NE_APT Run 2_Penultimate Prices EP3_Mar22-01002-1 | F12: 59.963 | G12: 1.0.0.105 | H12: 1 | I12: 6000 | J12: -41 | K12: 0 | L12: 24369 | M12: 41 | N12: 18510 | O12: 5971 | Q12: 0 | R12: 0 | S12: 696637077 | T12: Full | U12: 3.0.3.80 | V12: 3.0.3.80 | W12: 5/7/2019 | X12: 7/5/2019 13:24 | Y12: 0.39193287 | Z12: 3.0.3.82 | AA12: Keyboard | AB12: -1 | AC12: -999999 | AD12: 18469 | AE12: 39 | AF12: 5767 | AG12: 0 | AH12: 5 | AI12: 12702 | AJ12: 18469 | AK12: 11 | AL12: 11 | AM12: 1 | AN12: 11 | AO12: 0 | AP12: ? | AQ12: 4000 | AR12: 0 | AT12: 4000 | AU12: -12 | AV12: 204369 | AW12: 0 | AX12: 204369 | AY12: 12 | AZ12: 200481 | BA12: 4003 | BB12: 100 | BD12: 0 | BE12: 0 | BF12: 200374 | BG12: 204369 | BH12: 200469 | BI12: 7000 | BJ12: 0 | BL12: Keyboard | BM12: 7000 | BN12: -999999 | BO12: 206721 | BP12: 206721 | BQ12: 51 | BR12: 206452 | BS12: 0 | BT12: 100 | BU12: 1 | BV12: 269 | BW12: 206721 | BX12: 206405 | BY12: 213301 | BZ12: 206401 | CA12: 4000 | CB12: 0 | CD12: 4000 | CE12: -3 | CF12: 215369 | CG12: 0 | CH12: 215369 | CI12: 3 | CJ12: 211472 | CK12: 0 | CL12: 100 | CN12: 0 | CO12: 0 | CP12: 211369 | CQ12: 215369 | CR12: 211469 | CS12: 15 | CT12: 4 | CU12: 0 | CV12: 9 | CW12: 10 | CX12: 1 | CY12: 2 | CZ12: 3 | DA12: 4 | DB12: 5 | DC12: 6 | DD12: 7 | DE12: 8 | DF12: $30.00 each? | DG12: aptTrialProc | DH12: aptTrials | DI12: 0 | DJ12: 0 | DK12: 204484 | DL12: 15 | DM12: 204484 | DN12: 50 | DO12: 7000 | DP12: 0 | DR12: 7000 | DS12: -2300 | DT12: 211369 | DU12: 0 | DV12: 211369 | DW12: 2300 | DX12: 206769 | DY12: 4703 | DZ12: 100 | EB12: 0 | EC12: 0 | ED12: 206723 | EE12: 211369 | EF12: 204469 | EG12: 11
